Exception on /getResponse [GET]
Traceback (most recent call last):
  File "C:\Python\Python37\lib\site-packages\flask\app.py", line 2292, in wsgi_app
    response = self.full_dispatch_request()
  File "C:\Python\Python37\lib\site-packages\flask\app.py", line 1815, in full_dispatch_request
    rv = self.handle_user_exception(e)
  File "C:\Python\Python37\lib\site-packages\flask\app.py", line 1718, in handle_user_exception
    reraise(exc_type, exc_value, tb)
  File "C:\Python\Python37\lib\site-packages\flask\_compat.py", line 35, in reraise
    raise value
  File "C:\Python\Python37\lib\site-packages\flask\app.py", line 1813, in full_dispatch_request
    rv = self.dispatch_request()
  File "C:\Python\Python37\lib\site-packages\flask\app.py", line 1799, in dispatch_request
    return self.view_functions[rule.endpoint](**req.view_args)
  File "main.py", line 64, in getResponse
    intentTag = classes[result_array.index(max(result_array))]
IndexError: list index out of range
Exception on /getResponse [GET]
Traceback (most recent call last):
  File "C:\Python\Python37\lib\site-packages\flask\app.py", line 2292, in wsgi_app
    response = self.full_dispatch_request()
  File "C:\Python\Python37\lib\site-packages\flask\app.py", line 1815, in full_dispatch_request
    rv = self.handle_user_exception(e)
  File "C:\Python\Python37\lib\site-packages\flask\app.py", line 1718, in handle_user_exception
    reraise(exc_type, exc_value, tb)
  File "C:\Python\Python37\lib\site-packages\flask\_compat.py", line 35, in reraise
    raise value
  File "C:\Python\Python37\lib\site-packages\flask\app.py", line 1813, in full_dispatch_request
    rv = self.dispatch_request()
  File "C:\Python\Python37\lib\site-packages\flask\app.py", line 1799, in dispatch_request
    return self.view_functions[rule.endpoint](**req.view_args)
  File "main.py", line 64, in getResponse
    intentTag = classes[result_array.index(max(result_array))]
IndexError: list index out of range
Exception on /getResponse [GET]
Traceback (most recent call last):
  File "C:\Python\Python37\lib\site-packages\flask\app.py", line 2292, in wsgi_app
    response = self.full_dispatch_request()
  File "C:\Python\Python37\lib\site-packages\flask\app.py", line 1815, in full_dispatch_request
    rv = self.handle_user_exception(e)
  File "C:\Python\Python37\lib\site-packages\flask\app.py", line 1718, in handle_user_exception
    reraise(exc_type, exc_value, tb)
  File "C:\Python\Python37\lib\site-packages\flask\_compat.py", line 35, in reraise
    raise value
  File "C:\Python\Python37\lib\site-packages\flask\app.py", line 1813, in full_dispatch_request
    rv = self.dispatch_request()
  File "C:\Python\Python37\lib\site-packages\flask\app.py", line 1799, in dispatch_request
    return self.view_functions[rule.endpoint](**req.view_args)
  File "main.py", line 64, in getResponse
    intentTag = classes[result_array.index(max(result_array))]
IndexError: list index out of range
Exception on /getResponse [GET]
Traceback (most recent call last):
  File "C:\Python\Python37\lib\site-packages\flask\app.py", line 2292, in wsgi_app
    response = self.full_dispatch_request()
  File "C:\Python\Python37\lib\site-packages\flask\app.py", line 1815, in full_dispatch_request
    rv = self.handle_user_exception(e)
  File "C:\Python\Python37\lib\site-packages\flask\app.py", line 1718, in handle_user_exception
    reraise(exc_type, exc_value, tb)
  File "C:\Python\Python37\lib\site-packages\flask\_compat.py", line 35, in reraise
    raise value
  File "C:\Python\Python37\lib\site-packages\flask\app.py", line 1813, in full_dispatch_request
    rv = self.dispatch_request()
  File "C:\Python\Python37\lib\site-packages\flask\app.py", line 1799, in dispatch_request
    return self.view_functions[rule.endpoint](**req.view_args)
  File "main.py", line 71, in getResponse
    for intent in intents:
NameError: name 'intents' is not defined
Exception on /getResponse [GET]
Traceback (most recent call last):
  File "C:\Python\Python37\lib\site-packages\flask\app.py", line 2292, in wsgi_app
    response = self.full_dispatch_request()
  File "C:\Python\Python37\lib\site-packages\flask\app.py", line 1815, in full_dispatch_request
    rv = self.handle_user_exception(e)
  File "C:\Python\Python37\lib\site-packages\flask\app.py", line 1718, in handle_user_exception
    reraise(exc_type, exc_value, tb)
  File "C:\Python\Python37\lib\site-packages\flask\_compat.py", line 35, in reraise
    raise value
  File "C:\Python\Python37\lib\site-packages\flask\app.py", line 1813, in full_dispatch_request
    rv = self.dispatch_request()
  File "C:\Python\Python37\lib\site-packages\flask\app.py", line 1799, in dispatch_request
    return self.view_functions[rule.endpoint](**req.view_args)
  File "main.py", line 122, in getResponse
    result.append(response)
NameError: name 'response' is not defined
