Exception on /storeSurvey [GET]
Traceback (most recent call last):
  File "C:\Python\Python37\lib\site-packages\flask\app.py", line 2292, in wsgi_app
    response = self.full_dispatch_request()
  File "C:\Python\Python37\lib\site-packages\flask\app.py", line 1815, in full_dispatch_request
    rv = self.handle_user_exception(e)
  File "C:\Python\Python37\lib\site-packages\flask\app.py", line 1718, in handle_user_exception
    reraise(exc_type, exc_value, tb)
  File "C:\Python\Python37\lib\site-packages\flask\_compat.py", line 35, in reraise
    raise value
  File "C:\Python\Python37\lib\site-packages\flask\app.py", line 1813, in full_dispatch_request
    rv = self.dispatch_request()
  File "C:\Python\Python37\lib\site-packages\flask\app.py", line 1799, in dispatch_request
    return self.view_functions[rule.endpoint](**req.view_args)
  File "E:\USF\Courses\ISM6930-DSP\Projects\ResumeBot\main.py", line 390, in storeSurvey
    resumeBot.dbInsertSurvey(sessionId,userMessage,botResponse,rating)
  File "E:\USF\Courses\ISM6930-DSP\Projects\ResumeBot\main.py", line 307, in dbInsertSurvey
    c.execute('''INSERT INTO survey VALUES (?,?,?,?,?)''',insertValues)
sqlite3.OperationalError: database is locked
Exception on /storeSurvey [GET]
Traceback (most recent call last):
  File "C:\Python\Python37\lib\site-packages\flask\app.py", line 2292, in wsgi_app
    response = self.full_dispatch_request()
  File "C:\Python\Python37\lib\site-packages\flask\app.py", line 1815, in full_dispatch_request
    rv = self.handle_user_exception(e)
  File "C:\Python\Python37\lib\site-packages\flask\app.py", line 1718, in handle_user_exception
    reraise(exc_type, exc_value, tb)
  File "C:\Python\Python37\lib\site-packages\flask\_compat.py", line 35, in reraise
    raise value
  File "C:\Python\Python37\lib\site-packages\flask\app.py", line 1813, in full_dispatch_request
    rv = self.dispatch_request()
  File "C:\Python\Python37\lib\site-packages\flask\app.py", line 1799, in dispatch_request
    return self.view_functions[rule.endpoint](**req.view_args)
  File "E:\USF\Courses\ISM6930-DSP\Projects\ResumeBot\main.py", line 390, in storeSurvey
    resumeBot.dbInsertSurvey(sessionId,userMessage,botResponse,rating)
  File "E:\USF\Courses\ISM6930-DSP\Projects\ResumeBot\main.py", line 307, in dbInsertSurvey
    c.execute('''INSERT INTO survey VALUES (?,?,?,?,?)''',insertValues)
sqlite3.IntegrityError: UNIQUE constraint failed: survey.sessionId
Exception on /storeSurvey [GET]
Traceback (most recent call last):
  File "C:\Python\Python37\lib\site-packages\flask\app.py", line 2292, in wsgi_app
    response = self.full_dispatch_request()
  File "C:\Python\Python37\lib\site-packages\flask\app.py", line 1815, in full_dispatch_request
    rv = self.handle_user_exception(e)
  File "C:\Python\Python37\lib\site-packages\flask\app.py", line 1718, in handle_user_exception
    reraise(exc_type, exc_value, tb)
  File "C:\Python\Python37\lib\site-packages\flask\_compat.py", line 35, in reraise
    raise value
  File "C:\Python\Python37\lib\site-packages\flask\app.py", line 1813, in full_dispatch_request
    rv = self.dispatch_request()
  File "C:\Python\Python37\lib\site-packages\flask\app.py", line 1799, in dispatch_request
    return self.view_functions[rule.endpoint](**req.view_args)
  File "E:\USF\Courses\ISM6930-DSP\Projects\ResumeBot\main.py", line 390, in storeSurvey
    resumeBot.dbInsertSurvey(sessionId,userMessage,botResponse,rating)
  File "E:\USF\Courses\ISM6930-DSP\Projects\ResumeBot\main.py", line 307, in dbInsertSurvey
    c.execute('''INSERT INTO survey VALUES (?,?,?,?,?)''',insertValues)
sqlite3.OperationalError: database is locked
Exception on /getResponse [GET]
Traceback (most recent call last):
  File "C:\Python\Python37\lib\site-packages\flask\app.py", line 2292, in wsgi_app
    response = self.full_dispatch_request()
  File "C:\Python\Python37\lib\site-packages\flask\app.py", line 1815, in full_dispatch_request
    rv = self.handle_user_exception(e)
  File "C:\Python\Python37\lib\site-packages\flask\app.py", line 1718, in handle_user_exception
    reraise(exc_type, exc_value, tb)
  File "C:\Python\Python37\lib\site-packages\flask\_compat.py", line 35, in reraise
    raise value
  File "C:\Python\Python37\lib\site-packages\flask\app.py", line 1813, in full_dispatch_request
    rv = self.dispatch_request()
  File "C:\Python\Python37\lib\site-packages\flask\app.py", line 1799, in dispatch_request
    return self.view_functions[rule.endpoint](**req.view_args)
  File "E:\USF\Courses\ISM6930-DSP\Projects\ResumeBot\main.py", line 394, in getResponse
    if 'userMessage' in request.args:
  File "E:\USF\Courses\ISM6930-DSP\Projects\ResumeBot\main.py", line 295, in getBotResponse
  File "E:\USF\Courses\ISM6930-DSP\Projects\ResumeBot\main.py", line 177, in checkPattern
    response = modelResponse
NameError: name 'message' is not defined
Exception on /getResponse [GET]
Traceback (most recent call last):
  File "C:\Python\Python37\lib\site-packages\flask\app.py", line 2292, in wsgi_app
    response = self.full_dispatch_request()
  File "C:\Python\Python37\lib\site-packages\flask\app.py", line 1815, in full_dispatch_request
    rv = self.handle_user_exception(e)
  File "C:\Python\Python37\lib\site-packages\flask\app.py", line 1718, in handle_user_exception
    reraise(exc_type, exc_value, tb)
  File "C:\Python\Python37\lib\site-packages\flask\_compat.py", line 35, in reraise
    raise value
  File "C:\Python\Python37\lib\site-packages\flask\app.py", line 1813, in full_dispatch_request
    rv = self.dispatch_request()
  File "C:\Python\Python37\lib\site-packages\flask\app.py", line 1799, in dispatch_request
    return self.view_functions[rule.endpoint](**req.view_args)
  File "E:\USF\Courses\ISM6930-DSP\Projects\ResumeBot\main.py", line 402, in getResponse
    result = resumeBot.getBotResponse(actualMessage,previousContext,sessionId)
  File "E:\USF\Courses\ISM6930-DSP\Projects\ResumeBot\main.py", line 301, in getBotResponse
    response = self.checkPattern(actualMessage,context,previousContext,sessionId,response)
  File "E:\USF\Courses\ISM6930-DSP\Projects\ResumeBot\main.py", line 181, in checkPattern
    if "machine learning" in message:
NameError: name 'message' is not defined
